Workbook
Name IQ_CH: 110000
Name IQ_CQ: 5000
Name IQ_CY: 10000
Name IQ_DAILY: 500000
Name IQ_FH: 100000
Name IQ_FQ: 500
Name IQ_FWD_CY: 10001
Name IQ_FWD_CY1: 10002
Name IQ_FWD_CY2: 10003
Name IQ_FWD_FY: 1001
Name IQ_FWD_FY1: 1002
Name IQ_FWD_FY2: 1003
Name IQ_FWD_Q: 501
Name IQ_FWD_Q1: 502
Name IQ_FWD_Q2: 503
Name IQ_FY: 1000
Name IQ_LATESTK: 1000
Name IQ_LATESTQ: 500
Name IQ_LTM: 2000
Name IQ_LTMMONTH: 120000
Name IQ_MONTH: 15000
Name IQ_NTM: 6000
Name IQ_TODAY: 0
Name IQ_WEEK: 50000
Name IQ_YTD: 3000
Name IQ_YTDMONTH: 130000

Sheet Index
A1: Sheet | B1: Purpose and comments | C1: When is it used as an input? | D1: How is it filled?
A2: GEO | B2: It is used as the reference for ISO codes and labelling. It overrides the kountry command in Stata. Additionally, exceptions for NO, GB and AE apply in the same process (see do-file). | C2: 02a_combine_warehoiuses.do | D2: By hand (originally copy-pasted from ...)
A3: GEOReg | B3: Reference for ISO codes and labeling of regions within the United States | C3: not used | D3: By hand (originally copy-pasted from ...)
A4: d1_dashboard | B4: Store labels for the 5 components of varcode. See the store_labels_in_memory.do, which is called with the memorize_labels global throughout the code. | C4: 02a_combine_warehoiuses.do 03a_prepare_warehouse_for_tableau.do | D4: By hand
A5: d2_sector
A6: d3_vartype
A7: d4_concept
A8: d5_dboard_specific
A9: percentiles | B9: Labels the percentile variable. | C9: 02a_combine_warehouses.do 03a_prepare_warehouse_for_tableau.do | D9: By hand
A10: metadata_ineq
A11: metadata_topo | B11: built from soucre-specific metadata.dta (final table) | C11: 03a_prepare_warehouse_for_tableau.do | D11: Automatically in 02b
A12: Sources | B12: allows visualization only, not present in the warehouse. It combines “Metadata_0” and “EIG Taxes/data_inputs/EIGtax_mergeable.xlsx”. | C12: ? | D12: By hand

Sheet GEO
A1: Country | B1: GEO | C1: GEO3
A2: Afghanistan | B2: AF | C2: AFG
A3: Aland Islands | B3: AX | C3: ALA
A4: Albania | B4: AL | C4: ALB
A5: Algeria | B5: DZ | C5: DZA
A6: American Samoa | B6: AS | C6: ASM
A7: Andorra | B7: AD | C7: AND
A8: Angola | B8: AO | C8: AGO
A9: Anguilla | B9: AI | C9: AIA
A10: Antarctica | B10: AQ | C10: ATA
A11: Antigua and Barbuda | B11: AG | C11: ATG
A12: Argentina | B12: AR | C12: ARG
... A251: St. Kitts and Nevis | B251: KN | C251: KNA

Sheet GEOReg
A1: Country_Label | B1: Region_Label | C1: Meaning
A2: US | B2: AK | C2: Alasca | E2: Variable | F2: GeoReg
A3: US | B3: AL | C3: Alabama | E3: Meaning | F3: Region of the Country
A4: US | B4: AR | C4: Arkansas | E4: Type of Variable | F4: Character
A5: US | B5: AS | C5: American Samoa | E5: Maximum Length | F5: 2
A6: US | B6: AZ | C6: Arizona
A7: US | B7: CA | C7: California
A8: US | B8: CO | C8: Colorado
A9: US | B9: CT | C9: Connecticut
A10: US | B10: DC | C10: District of Columbia
A11: US | B11: DE | C11: Delaware
A12: US | B12: FL | C12: Florida
A13: US | B13: GA | C13: Georgia
A14: US | B14: GU | C14: Guam
A15: US | B15: HI | C15: Hawaii
A16: US | B16: IA | C16: Iowa
A17: US | B17: ID | C17: Idaho
... A59: _na | B59: _na | C59: not applicable

Sheet d1_dashboard
A1: code | B1: label | C1: description
A2: x | B2: Estate, Inheritance, and Gift Taxes | C2: The Estate, Inheritance, and Gift Taxes section contains a comprehensive database on the evolution of estate, inheritance, and gift (EIG) taxation, both across countries and (forthcoming) across the U.S. states. This section focuses on the taxation of wealth transfers, that is, transfers from one household or individual to another, either when the donor is living (inter vivos gifts) or at the time of the donor’s death (bequests). When assessing taxes, we distinguish among three types of taxes: those levied on estates (on the total amount bequeathed), on inheritances (on amounts received by individual recipients), and on gifts (given by living donors). The EIG sections contain information on statutory tax schedules, marginal tax rates, top marginal rates, exemption thresholds, and tax revenues. Information on effective taxation is also derived and presented. Understanding how governments tax these transfers is essential because bequests, inheritances, and inter vivos gifts are crucial economic resources for households and because their scale has increased substantially in recent decades relative to total national income.
A3: t | B3: Wealth Inequality Trends | C3: The Wealth Inequality Trends section presents the first comprehensive compilation of cross-national time-series data on wealth inequality. This section contains wealth inequality indicators (such as top shares and Gini coefficients) for many countries, as estimated in the existing literature for several countries. These data are accompanied by Method Tables that provide systematic assessments of the underlying concepts, methods, and sources for the estimation of wealth inequality trends. This section provides access to, and detailed information about, wealth inequality across countries and over time — in a single venue. To date, there is no comprehensive database that offers “off the shelf” indicators for researchers or others interested in wealth inequality levels and trends. Estimates of wealth distributions are much less settled than those of income distributions, and there is substantial controversy about how wealth inequality has evolved in recent years. A core value-added of this section of our dashboard is that users have access to detailed information about the values provided and methodological information that will help them to navigate the inevitable complexity.
A4: p | B4: Wealth Topography | C4: The Wealth Topography section includes cross-country data that captures, at the aggregate level, the evolution of household portfolios of assets and debt. Assets are metaphorically represented as “mountains and hills,” while debts are visualized as “seas” of debt. The data come from national accounts, household surveys, and a range of research projects and reports. These data offer a unique view of aggregate household balance sheets. Country-specific portfolios are shaped by, and reflect, national characteristics, including demographic trends, inflation and interest rates dynamics, features of financial and credit markets, the relative importance of stock exchanges versus banking systems, the strength of asset management industries, and the preferential tax treatment of assets, as well as the preferences of households and the generosity of pensions systems.
A5: i | B5: Inheritance Trends | C5: The section on Inheritance Trends is coming soon.
A6: z | B6: Supplementary Variables | C6: The supplementary variables provide additional context and comparability for the general warehouse data. They include data from sources such as the World Inequality Database (e.g., inflation adjustments, currency conversions, and macroeconomic metrics), the World Bank (e.g., country and income group classifications by region), and political data (e.g., government orientation based on party dominance).

Sheet d2_sector
A1: code | B1: label | C1: description
A2: na | B2: National Level | C2: The national sector gathers together all economic units controlled by residents' institutional sectors, such as government, households, businesses, and non-profits. It is distinct from the rest of the world sector.
A3: hs | B3: Households | C3: The household sector gathers together all individuals or group of individuals who live together, who pool their income and wealth, and make joint economic decisions (e.g., consumption). The household sector is one of the institutional sectors constituting the national economy.
A4: hn | B4: Households & NPISH | C4: The households and NPISH sector (non-profit institutions serving households) gathers together households (all individuals or group of individuals who live together, who pool their income and wealth, and make joint economic decisions) and non-profit organizations that primarily provide services to households (such as charities, religious institutions, and social clubs). The household and NPISH sector is one of the institutional sectors constituting the national economy.
A5: np | B5: NPISH | C5: The NPISH (non-profit institutions serving households) sector gathers together non-profit organizations that primarily provide services to households. This includes organizations such as charities, religious institutions, and social clubs. The NPISH sector is one of the institutional sectors constituting the national economy.
A6: tg | B6: EIG Tax, general government level | C6: The tax revenue information refers to the sum of estate, inheritance and gift taxes (EIG) for the general government sector.
A7: gg | B7: Gift Tax, general government level | C7: The tax revenue information refers to gift tax for the general government sector.
A8: tu | B8: EIG Tax, applies to unknown | C8: The status refers to a general estate, inheritance or gift tax, and the population group to which the tax is applied is not known from the sources available.
A9: te | B9: EIG Tax, applies to everybody | C9: Estate, inheritance or gift tax levied on anyone regardless of the degree of kinship or relationship to the deceased/donor.
A10: ec | B10: Estate Tax for Children | C10: Estate tax levied on children of the donor/decedent. The group also includes grandchildren, parents and grandparents, unless otherwise stated in the note.
A11: es | B11: Estate Tax for Spouse | C11: Estate tax levied on the spouse of the donor/decedent. The group includes the legal cohabitant unless otherwise specified in the note.
A12: el | B12: Estate Tax for Siblings | C12: Estate tax levied on the siblings of the donor/decedent. The group also includes children of siblings, unless otherwise stated in the note.
... A33: wt | B33: Net Wealth Tax on Total Net Worth | C33: Wealth tax on movable property and immovable property owned by individuals resident in the country, net of debt.

Sheet d3_vartype
A1: code | B1: label | C1: description
A2: dsh | B2: Share of Total Net Wealth | C2: The share of total net wealth refers to the percentage of the overall net wealth that individuals, household, or group owns. Net wealth is the value of assets (such as property, investments, and savings) minus any liabilities (such as debts or loans). For example, if the total net wealth of a country is €10,000 billion and a group's net wealth is €2,000 billion, their share of total net wealth would be 20%.
A3: owr | B3: Ownership Rate | C3: Share of ownership rate of a specific asset or good.
A4: csh | B4: Composition Share | C4: Composition share refers to the proportion or percentage of a particular category or component within a larger group or total. In the context of a wealth portfolio, composition share would refer to the percentage of a household's or a country's total wealth that is invested in a particular asset class, such as stocks, bonds, real estate, or cash. For example, if an individual's total wealth is €1 million and €400,000 of that is invested in stocks, the composition share of stocks in their wealth portfolio would be 40%.
A5: rat | B5: Rate | C5: In general, a rate is expressed as a percentage. For instance, the marginal inheritance tax rate is the amount of tax that is paid on an additional dollar of inheritance received. It represents the rate at which a person's tax liability increases as their inheritance increases. The concept can also be applied to the saving rate which refers to the percentage of disposable income that is saved or not spent on consumption.
A6: gin | B6: Gini Coefficient | C6: The Gini coefficient is a statistic that summarizes the overall distribution of income or wealth that is commonly published by statistical agencies. The coefficient ranges from 0 (perfect equality) to 100 (maximum inequality). A Gini coefficient of G per cent means that, if we take any 2 households from the population at random, the expected difference is 2G per cent of the mean. So that a rise in the Gini coefficient from 30 to 40 per cent implies that the expected difference (in wealth for instance) has gone up from 60 to 80 per cent of the average wealth.
A7: avg | B7: Average Wealth | C7: Average wealth refers to the total value of assets (such as property, savings, investments, and other financial assets) owned by a group of individuals or households divided by the total number of individuals or households in that group.
A8: rto | B8: Ratio | C8: A ratio describes the relationship between two quantities and is expressed as the quotient of one quantity divided by another. For example, if a country's total private net wealth is €10,000 billion and its total national income is €2,000 billion, the ratio of private wealth to national income is 5 to 1, as total private wealth is five times the amount of national income.
A9: thr | B9: Threshold | C9: A threshold represents a minimum or maximum value that must be met or exceeded, for instance, the minimum value of net wealth that is needed for an individual to belong to the group of the richest 1% of adults, or the maximum value of net wealth that is needed for an individual to belong to the group of the poorest 50% of adults.
A10: cat | B10: Categorical Variable | C10: A categorical variable represents data that can be divided into groups or categories.
A11: agg | B11: Aggregate | C11: Aggregate value for a given institutional sector. The value is reported without knowing whether transactions that occur between units within the same sector are eliminated or kept during the aggregation.
A12: agc | B12: Aggregate (Consolidated) | C12: Aggregate value for a given institutional sector for which transactions that occur between units within the same sector are eliminated.
... A15: per | B15: Period | C15: Numeric values that refer to a period (year, month, quarter).

Sheet d4_concept
A1: code | B1: label | C1: description
A2: netwea | B2: Net Wealth | C2: Net wealth is the sum of all tangible assets (real estate properties and land, valuables, plants, machineries, equipment, etc.) and intangible assets (stocks, bonds, balances of current, saving, and investment accounts, private pension and life insurance funds, etc.) minus the sum of all debts and liabilities (mortgages, loans, and credit card debt).
A3: nnhass | B3: Financial Assets & Fixed Capital of Personal Businesses | C3: Sum of all financial assets (such as stocks, shares or equities in corporations and quasi-corporations, corporate and government bonds, mutual funds, cash, current, savings and investment accounts, time deposits or certificates of deposit (CDs), accumulated balance in private pension funds, cash or reserve value of life insurance funds, etc.) and the fixed capital stock of small personal businesses of producer households (such as plants, machinery, equipment, inventories, software, and goodwill).
A4: fliabi | B4: Debt | C4: Debts, or liabilities, are financial obligations that generally result from borrowing. For households, the most common form of debt is the mortgage, a loan taken out by an individual or a household to purchase a home or other real estate properties. Other forms of debt include credit card debts, auto loans, and student loans.
A5: fliabm | B5: Debt secured by a mortgage | C5: Debt secured by a mortgage are loans taken out by an individual or a household to purchase a home or other real estate properties.
A6: facdbl | B6: Cash, Deposits, Bonds & Loans | C6: Cash can be held in the form of banknotes, coins, or digital currency. Bonds represent a loan made by households to a corporation or government entity and provide a fixed return to the investor in the form of interest payments. Deposits include both current accounts (available on demand) and savings accounts (generally interest-bearing instruments with limited withdrawal). Loans are the money lent to individuals or households for which they owe the principal and interest to the creditors.
A7: fadepb | B7: Bank accounts | C7: Current or savings accounts held at a bank (traditional bank only)
A8: fadepo | B8: Deposits | C8: Deposits include both current accounts (available on demand) and savings accounts (generally interest-bearing instruments with limited withdrawal).
A9: faeqfd | B9: Stocks, Business Equities & Fund Shares | C9: Stocks (or shares) and business equities are securities representing the ownership in a corporation or quasi-corporation and entitling the holder to a portion of the company's profits. Fund shares represent the participation in mutual or investment funds which are investment vehicles that pool together money from multiple investors to purchase a portfolio of securities such as stocks, bonds, or other assets.
A10: falipe | B10: Pensions & Life Insurance | C10: Private pension assets refer to funds that are set aside by an individual (or an employer) to provide income during retirement (excluding public pension and social security schemes). Pension assets can take the form of defined benefit plans (retirement income benefits are fixed) or defined contribution plans (retirement income benefits are dependent on contributions). Life insurance assets refer to the cash value or reserve value of a life insurance policy (where the policyholder pays premiums in exchange for a death benefit that is paid out to their beneficiaries upon their death).
A11: nfabus | B11: Fixed Capital of Personal Businesses | C11: Fixed capital of small personal businesses represents the non-financial assets that are used by a small personal business to produce goods or services and to support the ongoing operations of the business. This category includes both tangible assets (such as plants, machineries, equipment, inventories, valuables) and intangible assets (such as software and goodwill).
A12: nfadur | B12: Durable Goods | C12: Durable goods are goods used by households and individuals for consumption that may be used repeatedly over time (such as appliances, furniture, vehicles, boats, aircrafts, jewelry, antiques, works of art, and collections).
... A34: revgdp | B34: Total Revenue from Tax as % of Gross Domestic Product | C34: Total revenue from the specified tax at all government levels as a percentage of GDP.

Sheet d5_dboard_specific
A1: code | B1: label | C1: description | D1: dashboard
A2: ia | B2: Individuals - Adults | C2: Estimates of wealth inequality refer to the distribution across individual holders (depending on the source, at least 15, 16, 18, or 20 years old). In rare cases, this label also refers to individuals assumed to be holding the equivalized wealth of the household. The equivalence scale used in most cases is the “modified OECD scale,”, which gives a weight of 1 to the first adult, of 0.5 to each additional adult, and of 0.3 to each child. This means that total wealth of a family of 2 adults and 2 children is divided by 2.1. In other rare cases, it refers to the distribution across all individuals, irrespective of their age. | D2: =d1_dashboard!$B$3
A3: es | B3: Individuals - Adults (equal split) | C3: Total wealth of the household is divided equally between the two adult partners. Adults are generally defined as individuals at least 18 or 20 years old. This category could also include cases in which total wealth of the household is divided equally among all members of the household. | D3: =d1_dashboard!$B$3
A4: tu | B4: Tax Units | C4: Data on wealth holding refer to a group of individuals who are subject to the same tax laws (tax unit). In most cases, a tax unit is composed of one or more people who file a tax return together, such as a married couple filing jointly or a family filing as dependents on a parent's tax return. | D4: =d1_dashboard!$B$3
A5: ho | B5: Households | C5: Data on wealth holding refer to a household, defined as a group of people who live together in the same dwelling unit. The members of a household may be related by blood, marriage, or adoption, or they may be unrelated individuals who have chosen to live together for other reasons. | D5: =d1_dashboard!$B$3
A6: ga | B6: Gross Assets | C6: Gross assets are the total value of all assets before subtracting the value of debts and liabilities. | D6: =d1_dashboard!B$4
A7: na | B7: Net Assets | C7: Net assets are the total value of all assets after subtracting the value of debts and liabilities. | D7: =d1_dashboard!B$4
A8: lb | B8: Liabilities | C8: Liabilities are financial obligations or debts that an individual, company, or organization owes to another party. | D8: =d1_dashboard!B$4
A9: __ | B9: Not Applicable | C9: Not Applicable | D9: =d1_dashboard!B$4
A10: 00 | B10: Non-Bracket Specific | C10: A general variable not referring to any specific bracket of the tax schedule | D10: =d1_dashboard!B$2
A11: 01 | B11: Bracket n 01 | C11: A tax policy variable applicable to the bracket n 01 of the tax schedule | D11: =d1_dashboard!B$2
A12: 02 | B12: Bracket n 02 | C12: A tax policy variable applicable to the bracket n 02 of the tax schedule | D12: =d1_dashboard!B$2
A13: 03 | B13: Bracket n 03 | C13: A tax policy variable applicable to the bracket n 03 of the tax schedule | D13: =d1_dashboard!B$2
A14: 04 | B14: Bracket n 04 | C14: A tax policy variable applicable to the bracket n 04 of the tax schedule | D14: =d1_dashboard!B$2
A15: 05 | B15: Bracket n 05 | C15: A tax policy variable applicable to the bracket n 05 of the tax schedule | D15: =d1_dashboard!B$2
A16: 06 | B16: Bracket n 06 | C16: A tax policy variable applicable to the bracket n 06 of the tax schedule | D16: =d1_dashboard!B$2
A17: 07 | B17: Bracket n 07 | C17: A tax policy variable applicable to the bracket n 07 of the tax schedule | D17: =d1_dashboard!B$2
A18: 08 | B18: Bracket n 08 | C18: A tax policy variable applicable to the bracket n 08 of the tax schedule | D18: =d1_dashboard!B$2
A19: 09 | B19: Bracket n 09 | C19: A tax policy variable applicable to the bracket n 09 of the tax schedule | D19: =d1_dashboard!B$2
A20: 10 | B20: Bracket n 10 | C20: A tax policy variable applicable to the bracket n 10 of the tax schedule | D20: =d1_dashboard!B$2
A21: 11 | B21: Bracket n 11 | C21: A tax policy variable applicable to the bracket n 11 of the tax schedule | D21: =d1_dashboard!B$2
... A39: 29 | B39: Bracket n 29 | C39: A tax policy variable applicable to the bracket n 29 of the tax schedule | D39: =d1_dashboard!B$2
A40: ef | B40: Economic Flow | C40: Estimates from national accounts | D40: Inheritance Trends
A41: ff | B41: Fiscal Flow | C41: Estimates from fiscal records | D41: Inheritance Trends

Sheet percentiles
A1: percentile | B1: label_percentile | C1: description_percentile
A2: p0p10 | B2: Poorest 10% | C2: Group representing the bottom decile (10%) of the wealth distribution, meaning that 90% of the population would have higher wealth levels in comparison.
A3: p0p20 | B3: Poorest 20% | C3: Group representing the bottom quintile (20%) of the wealth distribution, meaning that 80% of the population would have higher wealth levels in comparison.
A4: p0p25 | B4: Poorest 25% | C4: Group representing the bottom quartile (25%) of the wealth distribution, meaning that 75% of the population would have higher wealth levels in comparison.
A5: p0p30 | B5: Poorest 30% | C5: Group representing the bottom 30% of the wealth distribution, meaning that 70% of the population would have higher wealth levels in comparison.
A6: p0p40 | B6: Poorest 40% | C6: Group representing the bottom 40% of the wealth distribution, meaning that 60% of the population would have higher wealth levels in comparison.
A7: p0p50 | B7: Poorest 50% | C7: Group representing the poorest half of the wealth distribution, meaning that 50% of the population would have higher wealth levels in comparison.
A8: p0p60 | B8: Poorest 60% | C8: Group representing the bottom 60% of the wealth distribution
A9: p0p70 | B9: Poorest 70% | C9: Group representing the bottom 70% of the wealth distribution
A10: p0p80 | B10: Poorest 80% | C10: Group representing the bottom 80% of the wealth distribution
A11: p0p90 | B11: Poorest 90% | C11: Group representing the bottom 90% of the wealth distribution
A12: p0p99 | B12: Poorest 99% | C12: Group representing the bottom 99% of the wealth distribution
... A28: p75p100 | B28: Richest 25% | C28: Group representing the top quartile (25%) of the wealth distribution, meaning that 75% of the population would have lower wealth levels in comparison.

Sheet data_type
A1: label | B1: description
A2: Wealth survey | B2: The series has been estimated using only wealth survey data.
A3: Wealth survey (with adjustments) | B3: The series has been estimated from wealth survey data that has been adjusted, especially at the top. Adjustment methods comprise rich-list based adjustment als well as pure reweighting methods.
A4: Wealth survey and national accounts | B4: The series has been estimated using wealth survey data that has been brought into alignment with macroeconomic balance sheets.
A5: Rich list | B5: The series has been estimated using only rich list data points.
A6: Capital income tax data, wealth survey, and national accounts | B6: The series has been estimated via a capitalization approach that uses data on income due to the ownership of wealth (capital income), supported by survey data, and the series aligns with macroeconomic balance sheets.
A7: Capital income tax data, other sources, and national accounts | B7: The series has been estimated via a capitalization approach that uses data on income due to the ownership of wealth (capital income), additional data other than household survey data, and the series aligns with macroeconomic balance sheets.
A8: Inheritance/estate tax-based | B8: The series has been estimated via a mortality-multiplier approach using inheritance and/or estate tax data.
A9: Inheritance/estate tax data, wealth survey, and national accounts | B9: The series has been estimated via a mortality-multiplier approach using inheritance and/or estate tax data, supported by survey data, and the corresponding aggregates align with macroeconomic balance sheets.
A10: Wealth tax/register-based | B10: The series has been estimated from wealth tax data or register data on wealth.
A11: Wealth tax/register data and estate tax data | B11: The series has been estimated from wealth tax data or register data on wealth used in conjunction with estate/inheritance tax data.
A12: Wealth tax/register data, other sources, and national accounts | B12: The series has been estimated from wealth tax data or register data on wealth in conjunction with additional sources other than estate/inheritance tax data, and it has been brought into alignment with macroeconomic balance sheets.
A13: Mix of sources and methods | B13: Any series that rely substantively on a combination of sources and methods and that cannot be listed under any of the other classifications.

Sheet mtable_fields
A1: Field name | B1: Field description
A2: Legend | B2: The name of the source.
A3: Period covered and data points | B3: The range from the first to last year included in the series published in the warehouse; the precise years and/or quarters for which data points are available; the total number of years and/or quarters containing data points.
A4: Data type | B4: A categorization of the data type(s) used in the series published in the warehouse.
A5: Inequality indicators | B5: The precise inequality measures covered in the series. See the description of the varcode (vartype) for more information on these measures.
A6: Data sources used in the research | B6: A list of all data sources used in the estimation of wealth inequality and the year(s) they provide data for. Note that not all of these data sources are necessarily relevant to the specific series we publish in the database. Full citation information for these sources is not typically included in the references section, and should instead be located from the source itself.
A7: Unit of analysis | B7: The unit of analysis of the series published in the warehouse. See the description of the varcode (dashboard-specific) for details.
A8: Definition of wealth | B8: The precise definition of wealth underlying the wealth inequality estimates provided by the source.
A9: Method of estimation | B9: A brief summary of the estimation method of the series published in the warehouse.
A10: Method of estimation (detailed) | B10: A more detailed explanation (when applicable) of the estimation method of the series published in the warehouse.
A11: Valuation of assets | B11: How specific assets and liabilities have been valuated.
A12: Treatment of private pensions | B12: Whether any private pensions are included in the wealth definition, and if applicable, how they have been valuated.
... A21: Total wealth estimate and source | B21: The manner and source of the aggregate wealth estimate underlying the series.
A22: Robustness/sensitivity analyses
A23: Alternative/additional derived series
A24: References | B24: A bibliography for the sources cited parenthetically in the table’s analysis (i.e., not necessarily those listed in the data sources used in the research section). Any important references that are called out by title in the analysis (such as appendices, data files, or a working paper version of the source) are listed first, with their reference information and any downloadable files being available at their hyperlinked entry in the Data Sources Library.

Sheet source_type
A1: label | B1: description
A2: Cross-national official statistics | B2: Cross-national data from official institutions, such as national accounts from central banks.
A3: Cross-national official survey data | B3: Cross-national survey data from official institutions, such as household finance surveys from national statistical offices.
A4: Cross-national corporate research | B4: Cross-national research published by corporate entities, such as private consultancy firms.
A5: Cross-national academic research | B5: Cross-national research published by academic institutions, such as an academic journal article.
A6: Cross-national government research | B6: Cross-national research published by government institutions, such as government-commissioned reports.
A7: Official statistics | B7: Data from official institutions, such as national accounts from a country’s central bank.
A8: Official survey data | B8: Survey data from official institutions, such as household finance surveys from a country’s national statistical office.
A9: Corporate research | B9: Research published by corporate entities, such as private consultancy firms.
A10: Academic research | B10: Research published by academic institutions, such as an academic journal article.
A11: Government research | B11: Research published by government institutions, such as government-commissioned reports.
A12: Government legislation | B12: The actual text of public legislation.
... A14: Government documents | B14: Other texts published by government institutions, such as tax documents, forms, or descriptive reports.

Sheet Sources
A1: Section | B1: AggSource | C1: Legend | D1: Source | E1: Data_Type | F1: Link | G1: Ref_link | H1: Citekey | I1: Inclusion_in_Warehouse | J1: Multigeo_Reference | K1: Metadata | L1: Metadatalink | M1: QcommentsforTA | N1: TAreply | O1: TAcomments | P1: ARJcomments | Q1: ARJreplies | R1: SeeAggSourcelisthere
A2: Wealth Inequality | B2: Official survey data | C2: Australian Bureau of Statistics (2022) | D2: ABS | E2: Wealth survey and national accounts | F2: https://www.abs.gov.au/statistics/economy/finance/household-income-and-wealth-australia/latest-release | G2: https://bibbase.org/network/publication/australianbureauofstatistics-australiannationalaccountsdistributionofhouseholdincomeconsumptionandwealth-2022 | H2: AustralianBureauofStatistics2022_AustralianNationalAccountsDistributionHousehold
A3: Wealth Inequality | B3: Official survey data | C3: Australian Bureau of Statistics (2022) Appendix | D3: ABSAppendix | E3: Wealth survey and national accounts | F3: https://www.abs.gov.au/AUSSTATS/abs@.nsf/Lookup/5204.0.55.009Main+Features12009-10?OpenDocument | G3: https://bibbase.org/network/publication/australianbureauofstatistics-5204055009informationpaperaustraliannationalaccountsdistributionofhouseholdincomeconsumptionandwealth200910-2013 | H3: AustralianBureauofStatistics2022app | I3: No
A4: Inheritance Trends | B4: Academic research | C4: Acciari and Morelli (2022) | D4: Acciari2021 | F4: https://doi.org/10.7208/chicago/9780226816043-009 | H4: Acciari2021
A5: Wealth Inequality | B5: Academic research | C5: Acciari et al. (2024) | D5: Acciari2024 | E5: Inheritance/estate tax data, household survey, and national accounts | F5: https://doi.org/10.1093/jeea/jvae002 | G5: https://bibbase.org/network/publication/acciari-alvaredo-morelli-theconcentrationofpersonalwealthinitaly19952016-2024 | H5: Acciarietal2024
A6: Wealth Inequality | B6: Academic research | C6: Acciari et al. (2024) Appendix | D6: Acciari2024Appendix | E6: Inheritance/estate tax data, household survey, and national accounts | F6: https://doi.org/10.1093/jeea/jvae002 | G6: https://bibbase.org/network/publication/acciari-alvaredo-morelli-onlineappendixtheconcentrationofpersonalwealthinitaly19952016-2024 | H6: Acciarietal2024app | I6: No
A7: Taxes on Wealth | B7: Government research | C7: Coordination of State and Federal Inheritance, Estate, and Gift Taxes (1961) | D7: ACIR1961 | F7: https://digital.library.unt.edu/ark:/67531/metadc1458/ | G7: https://bibbase.org/network/publication/unitedstatesadvisorycommissiononintergovernmentalrelations-coordinationofstateandfederalinheritanceestateandgifttaxesacommissionreport-1961 | H7: UnitedStatesAdvisoryCommissiononIntergovernmentalRelations1961_CoordinationStateFederalInheritanceEstate
A8: Taxes on Wealth | B8: Government research | C8: State and Federal Taxes: Significant Features (1968) | D8: ACIR1968 | F8: https://library.unt.edu/gpo/acir/Reports/information/m-37.pdf | G8: https://bibbase.org/network/publication/unitedstatesadvisorycommissiononintergovernmentalrelations-stateandfederaltaxessignificantfeatures1968aninformationreport-1968 | H8: UnitedStatesAdvisoryCommissiononIntergovernmentalRelations1968_StateFederalTaxesSignificantFeatures
A9: Wealth Inequality | B9: Academic research | C9: Advani et al. (2021) | D9: Advani2021 | E9: Household survey (with adjustments) | F9: https://doi.org/10.1111/1475-5890.12286 | G9: https://bibbase.org/network/publication/advani-bangham-leslie-theukswealthdistributionandcharacteristicsofhighwealthhouseholds-2021 | H9: Advanietal2021
A10: Wealth Inequality | B10: Academic research | C10: Advani et al. (2021) Appendix | D10: Advani2021Appendix | E10: Household survey (with adjustments) | F10: https://doi.org/10.1111/1475-5890.12286 | G10: https://bibbase.org/network/publication/advani-bangham-leslie-theukswealthdistributionandcharacteristicsofhighwealthhouseholdsonlineappendix-2021 | H10: Advanietal2021app | I10: No
A11: Wealth Inequality | B11: Academic research | C11: Advani et al. (2021) Data | D11: Advani2021Data | E11: Household survey (with adjustments) | F11: https://arunadvani.com/research.html | G11: https://bibbase.org/network/publication/advani-bangham-leslie-theukswealthdistributionandcharacteristicsofhighwealthhouseholdsdatafile-2021 | H11: Advanietal2021data | I11: No
A12: Taxes on Wealth | B12: Academic research | C12: Aiken (2007) | D12: Aiken2007 | F12: https://digitalcommons.unl.edu/agecon_cornhusker/325/ | G12: https://bibbase.org/network/publication/aiken-2007legislaturerepealsestatetaxandreducesinheritancetax-2007 | H12: Aiken2007 | R12: In Library, not standardized (i.e., state sources moved out of lib)
A13: Wealth Inequality | B13: Academic research | C13: Albers et al. (2022) | D13: Albers2022 | E13: Wealth tax/register data, other sources, and national accounts | F13: https://doi.org/10.2139/ssrn.4103952 | G13: https://bibbase.org/network/publication/albers-bartels-schularick-wealthanditsdistributioningermany18952018-2022 | H13: Albersetal2022
A14: Wealth Inequality | B14: Academic research | C14: Albers et al. (2022) Appendix | D14: Albers2022Appendix | E14: Wealth tax/register data, other sources, and national accounts | F14: https://sites.google.com/site/charlottedsbartels/work-in-progress?authuser=0 | G14: https://bibbase.org/network/publication/albers-bartels-schularick-dataappendixforwealthanditsdistributioningermany18952018-2022 | H14: Albersetal2022app | I14: No
A15: Wealth Inequality | B15: Academic research | C15: Albers et al. (2022) Data | D15: Albers2022Data | E15: Wealth tax/register data, other sources, and national accounts | F15: https://bibbase.org/network/publication/albers-bartels-schularick-wealthanditsdistributioningermany18952018datafiles-2022 | G15: https://bibbase.org/network/publication/albers-bartels-schularick-wealthanditsdistributioningermany18952018datafiles-2022 | H15: Albersetal2022data | I15: No
A16: Wealth Inequality | B16: Academic research | C16: Alvaredo & Saez (2010) | D16: Alvaredo2010 | E16: Wealth tax/register-based | F16: https://global.oup.com/academic/product/top-incomes-9780199286898?cc=us&lang=en&# | G16: https://bibbase.org/network/publication/alvaredo-saez-incomeandwealthconcentrationinspaininahistoricalandfiscalperspective-2010 | H16: AlvaredoSaez2010
A17: Wealth Inequality | B17: Academic research | C17: Alvaredo & Saez (2010) Data | D17: Alvaredo2010Data | E17: Wealth tax/register-based | F17: https://eml.berkeley.edu/~saez/ | G17: https://bibbase.org/network/publication/alvaredo-saez-incomeandwealthconcentrationinspaininahistoricalandfiscalperspectivedatafile-2010 | H17: AlvaredoSaez2010data | I17: No
A18: Inheritance Trends | B18: Academic research | C18: Alvaredo et al. (2017) | D18: Alvaredo2017 | F18: https://onlinelibrary.wiley.com/doi/abs/10.1111/ecca.12233 | H18: Alvaredo2017
A19: Wealth Inequality | B19: Academic research | C19: Alvaredo et al. (2018) | D19: Alvaredo2018 | E19: Inheritance/estate tax-based | F19: https://doi.org/10.1016/j.jpubeco.2018.02.008 | G19: https://bibbase.org/network/publication/alvaredo-atkinson-morelli-topwealthsharesintheukovermorethanacentury-2018 | H19: Alvaredoetal2018
A20: Wealth Inequality | B20: Academic research | C20: Alvaredo et al. (2018) Appendix | D20: Alvaredo2018Appendix | E20: Inheritance/estate tax-based | F20: https://doi.org/10.1016/j.jpubeco.2018.02.008 | G20: https://bibbase.org/network/publication/alvaredo-atkinson-morelli-topwealthsharesintheukovermorethanacenturyappendicesforonlinepublication-2018 | H20: Alvaredoetal2018app | I20: No
A21: Wealth Inequality | B21: Academic research | C21: Alvaredo et al. (2018) Data | D21: Alvaredo2018Data | E21: Inheritance/estate tax-based | F21: https://doi.org/10.1016/j.jpubeco.2018.02.008 | G21: https://bibbase.org/network/publication/alvaredo-atkinson-morelli-topwealthsharesintheukovermorethanacenturydatafile-2018 | H21: Alvaredoetal2018data | I21: No
A22: Wealth Inequality | B22: Cross-national academic research | C22: Alvaredo et al. (2024) | D22: Alvaredo2024 | E22: Inheritance/estate tax-based | F22: https://osf.io/preprints/socarxiv/a4frb_v2 | H22: Alvaredo2024
A23: Wealth Inequality | B23: Academic research | C23: Anand & Kumar (2022) | D23: Anand2022 | E23: Household survey (with adjustments) | F23: https://doi.org/10.31235/osf.io/726c8 | G23: https://bibbase.org/network/publication/anand-kumar-theskyandthestratosphereconcentratedwealthinindiaduringthelostdecade-2022 | H23: AnandKumar2022
A24: Wealth Inequality | B24: Academic research | C24: Anand & Kumar (2022) Data | D24: Anand2022Data | E24: Household survey (with adjustments) | F24: https://doi.org/10.31235/osf.io/726c8 | G24: https://bibbase.org/network/publication/anand-kumar-theskyandthestratosphereconcentratedwealthinindiaduringthelostdecadesupplementarydata-2022 | H24: AnandKumar2022data | I24: No
A25: Taxes on Wealth | B25: Cross-national corporate research | C25: Anderson (1999) | D25: Anderson2009 | F25: https://www.forbes.com/global/1999/1227/166_01.html?sh=513773192f64 | G25: https://bibbase.org/network/publication/anderson-theworstplacestodie-1999 | H25: Anderson1999
A26: Wealth Topography | B26: Cross-national government research | C26: Atlas of the Offshore World | D26: AOW | F26: https://atlas-offshore.world/dataset/offshore-financial | G26: https://bibbase.org/network/publication/atlasoftheoffshoreworld-offshorefinancialwealth-2023 | H26: AtlasoftheOffshoreWorld2023_OffshoreFinancialWealth
A27: Inheritance Trends | B27: Academic research | C27: Apostel (2025) | D27: Apostel2025 | F27: https://www.econstor.eu/handle/10419/322377 | H27: Apostel2025
A28: Supplementary Variables | B28: Academic research | C28: Comparative Political Data Set, 1960-2021 | D28: Armingeon2023 | F28: https://cpds-data.org/ | G28: https://bibbase.org/network/publication/armingeon-engler-leemann-weisstanner-comparativepoliticaldataset19602021-2023 | H28: Armingeonetal2023
A29: Wealth Inequality | B29: Academic research | C29: Assouad (2021) | D29: Assouad2021 | E29: Rich list | F29: https://wid.world/document/rethinking-lebanese-economic-miracle-extreme-concentration-income-wealth-lebanon-2005-2014-wid-world-working-paper-201713/ | G29: https://bibbase.org/network/publication/assouad-rethinkingthelebaneseeconomicmiracletheextremeconcentrationofincomeandwealthinlebanon20052014-2021 | H29: Assouad2021
A30: Wealth Inequality | B30: Academic research | C30: Assouad (2021) Data | D30: Assouad2021Data | E30: Rich list | F30: https://wid.world/methodology/#library-browse-by-country-lebanon | G30: https://bibbase.org/network/publication/assouad-datafilestorethinkingthelebaneseeconomicmiracletheextremeconcentrationofincomeandwealthinlebanon20052014-2017 | H30: Assouad2021data | I30: No
A31: Inheritance Trends | B31: Academic research | C31: Atkinson (2018) | D31: Atkinson2012 | F31: http://piketty.pse.ens.fr/files/Atkinson2012.pdf | H31: Atkinson2012
A32: Taxes on Wealth | B32: Government legislative info | C32: Australian Tax Office: Deceased Estates | D32: ATO | F32: https://www.ato.gov.au/individuals/deceased-estates/ | G32: https://bibbase.org/network/publication/australiantaxationoffice-deceasedestates-2023 | H32: AustralianTaxationOffice2023
A33: Taxes on Wealth | B33: Government legislation | C33: Austria Tax Law (1955) | D33: AustriaTaxLaw_1955 | F33: https://www.ris.bka.gv.at/Dokumente/BgblPdf/1955_141_0/1955_141_0.pdf | G33: https://bibbase.org/network/publication/republicofaustria-inheritanceandgifttaxact1955-1955 | H33: RepublicofAustria1955_InheritanceGiftTaxAct1955
A34: Taxes on Wealth | B34: Government legislation | C34: Austria Tax Law (1968) | D34: AustriaTaxLaw_1968 | F34: https://www.ris.bka.gv.at/Dokumente/BgblPdf/1968_15_0/1968_15_0.pdf | G34: https://bibbase.org/network/publication/republicofaustria-inheritanceandgifttaxactamendment1967-1968 | H34: RepublicofAustria1968_InheritanceGiftTaxActAmendment
A35: Taxes on Wealth | B35: Government legislation | C35: Austria Tax Law (2001) | D35: AustriaTaxLaw_2001 | F35: https://www.ris.bka.gv.at/Dokumente/BgblPdf/2001_59_1/2001_59_1.pdf | G35: https://bibbase.org/network/publication/republicofaustria-eurotaxconversionacteurostug2001-2001 | H35: RepublicofAustria2001_EuroTaxConversionActEuroStUG
A36: Taxes on Wealth | B36: Government legislation | C36: Austria Tax Law (2008) | D36: AustriaTaxLaw_2008 | F36: https://www.ris.bka.gv.at/eli/bgbl/I/2008/85 | G36: https://bibbase.org/network/publication/republicofaustria-inheritanceandgifttaxact1955-1955 | H36: AustriaTaxLaw_2008
A37: Taxes on Wealth | B37: Government documents | C37: Arizona 2006 Tax Handbook History - Estate Tax | D37: AZ_Est2006 | F37: https://www.azleg.gov/jlbc/06taxbook/estatetax.pdf | G37: https://bibbase.org/network/publication/arizonajointlegislativebudgetcommittee-historicaltaxlawchangesestatetax-2006 | H37: ArizonaJointLegislativeBudgetCommittee2006_HistoricalTaxLawChangesEstate
A38: Taxes on Wealth | B38: Academic research | C38: Bakija (2016) | D38: Bakija2016 | F38: https://web.williams.edu/Economics/bakija/Documentation_EITaxCalc.pdf | G38: https://bibbase.org/network/publication/bakija-documentationforafederalandstateinheritanceandestatetaxcalculator-2016 | H38: Bakija2016
A39: Taxes on Wealth | B39: Government research | C39: Baldwin (1977) | D39: Baldwin1977 | F39: https://hdl.handle.net/2027/wu.89096584909 | G39: https://bibbase.org/network/publication/baldwin-comparisonofestatetaxationandinheritancetaxation-1977 | H39: Baldwin1977
A40: Taxes on Wealth | B40: Corporate research | C40: Estate and Inheritance Taxes | D40: Ballotopedia | F40: https://ballotpedia.org/Estate_and_inheritance_taxes | G40: https://bibbase.org/network/publication/ballotpedia-estateandinheritancetaxes | H40: Ballotpedia_EstateInheritanceTaxes
...

Sheet crosswalk_warehouseviz_labels
A1: from_varname | B1: to_varname_long | C1: to_varname
A2: _1_dashboard | B2: d1_dashboard_varname | C2: d1_code
A3: _2_sector | B3: d2_sector_code | C3: d2_code
A4: _3_vartype | B4: d3_vartype_code | C4: d3_code
A5: _4_concept | B5: d4_concept_code | C5: d4_code
A6: _5_dboard_specific | B6: d5_dboard_specific_code | C6: d5_code
A7: _1_dashboard_lab | B7: d1_dashboard_label | C7: d1_label
A8: _2_sector_lab | B8: d2_sector_label | C8: d2_label
A9: _3_vartype_lab | B9: d3_vartype_label | C9: d3_label
A10: _4_concept_lab | B10: d4_concept_label | C10: d4_label
A11: _5_dboard_specific_lab | B11: d5_dboard_specific_label | C11: d5_label
A12: varcode | C12: varcode
A13: percentile | C13: percentile
A14: percentile_label | C14: percentile_label
A15: WhichDistrib | C15: WhichDistrib
A16: indicator_label | C16: indicator_label
A17: metadata | C17: metadata
A18: longname | C18: longname
A19: source | C19: source
A20: year | C20: year
A21: GEO | C21: GEO

Sheet widcodes
A1: variable | B1: shortname | C1: simpledes
A2: inyixx | B2: National income price index | C2: Price index that reflects the evolution of the price level for all new, domestically produced, final goods and services in the economy.
A3: mgdpro | B3: Gross domestic product | C3: Gross domestic product is the total value of goods and services produced by the national economy.The national economy - in the national accounts sense - includes all domestic sectors, i.e. all entities that are resident of a given country (in the sense of their economic activity), whether they belong to the private sector, the corporate sector, the governement sector.
A4: mnninc | B4: National income | C4: National income aims to measure the total income available to the residents of a given country. It is equal to the gross domestic product (the total value of goods and services produced on the territory of a given country during a given year), minus fixed capital used in production processes (e.g. replacement of obsolete machines or maintenance of roads) plus the net foreign income earned by residents in the rest of the world.// National income has many limitations. However it is the only income concept that has an internationally agreed definition (established by the United Nations System of National Accounts, see SNA 2008). So we use it as our reference concept (with tax havens correction). To be improved.The national economy - in the national accounts sense - includes all domestic sectors, i.e. all entities that are resident of a given country (in the sense of their economic activity), whether they belong to the private sector, the corporate sector, the governement sector.
A5: mpweal | B5: Net private wealth | C5: Net private wealth is the total value of non-financial and financial assets (housing, land, deposits, bonds, equities of corporations, etc.) held by private owners (households and foundations), minus their debts. The private sector - in the national accounts sense - includes the personal sector (households) and the non-profit sector (foundations, religious organizations, etc.). In certain countries, availables sources do not allow to decompose the wealth owned by each of these two sub-sectors, and we only provide total net private wealth.
A6: ntaxma | B6: Number of tax units - married couples & single adults | C6: Number of married couples and single adults as tax units.
A7: xlceup | B7: PPP conversion factor, LCU per EUR | C7: PPP conversion factor of current local currency to current PPP EUR.
A8: xlceux | B8: Market exchange rate, LCU per EUR | C8: Official exchange rate of the local currency to EUR.
A9: xlcusp | B9: PPP conversion factor, LCU per USD | C9: PPP conversion factor of current local currency to current PPP USD.
A10: xlcusx | B10: Market exchange rate, LCU per USD | C10: Official exchange rate of the local currency to USD.
A11: xlcyup | B11: PPP conversion factor, LCU per CNY | C11: PPP conversion factor of current local currency to current PPP CNY.
A12: xlcyux | B12: Market exchange rate, LCU per CNY | C12: Official exchange rate of the local currency to CNY.
... A14: npopul | B14: Population | C14: Number of individuals in a group.

Sheet SourceAliases
A1: Alias | B1: Source | C1: Citekey | D1: Record_ID | E1: Note
A2: CS_ineq | B2: CS | C2: CreditSuisse_CreditSuisseGlobalWealthReport | D2: src-cs-ineq | E2: Legacy dashboard/source-manager code mapped to canonical source code.
A3: CS_topo | B3: CS | C3: CreditSuisse_CreditSuisseGlobalWealthReport | D3: src-cs-ineq | E3: Legacy dashboard/source-manager code mapped to canonical source code.
A4: ECB_DWA_ineq | B4: ECB_DWA | C4: EuropeanCentralBank2024_DistributionalWealthAccounts | D4: src-ecb-dwa-ineq | E4: Legacy dashboard/source-manager code mapped to canonical source code.
A5: ECB_DWA_topo | B5: ECB_DWA | C5: EuropeanCentralBank2024_DistributionalWealthAccounts | D5: src-ecb-dwa-ineq | E5: Legacy dashboard/source-manager code mapped to canonical source code.
A6: HFCS_ineq | B6: HFCS | C6: HouseholdFinanceandConsumptionNetwork2021 | D6: src-hfcs-ineq | E6: Legacy dashboard/source-manager code mapped to canonical source code.
A7: HFCS_topo | B7: HFCS | C7: HouseholdFinanceandConsumptionNetwork2021 | D7: src-hfcs-ineq | E7: Legacy dashboard/source-manager code mapped to canonical source code.
A8: LWS_ineq | B8: LWS | C8: LIS_LuxembourgWealthStudyDatabase | D8: src-lws-ineq | E8: Legacy dashboard/source-manager code mapped to canonical source code.
A9: LWS_topo | B9: LWS | C9: LIS_LuxembourgWealthStudyDatabase | D9: src-lws-ineq | E9: Legacy dashboard/source-manager code mapped to canonical source code.
A10: WID_ineq | B10: WID | C10: WorldInequalityDatabase_Data | D10: src-wid-ineq | E10: Legacy dashboard/source-manager code mapped to canonical source code.
A11: WID_topo | B11: WID | C11: WorldInequalityDatabase_Data | D11: src-wid-ineq | E11: Legacy dashboard/source-manager code mapped to canonical source code.
